GPU available: True (cuda), used: True
TPU available: False, using: 0 TPU cores
IPU available: False, using: 0 IPUs
HPU available: False, using: 0 HPUs
`Trainer(limit_val_batches=1.0)` was configured so 100% of the batches will be used..
`Trainer(val_check_interval=1.0)` was configured so validation will run at the end of the training epoch..
[rank: 0] Global seed set to 1647
Initializing distributed: GLOBAL_RANK: 0, MEMBER: 1/1
----------------------------------------------------------------------------------------------------
distributed_backend=nccl
All distributed processes registered. Starting with 1 processes
----------------------------------------------------------------------------------------------------
Restoring states from the checkpoint path at ../3DGS-GPT/runs/02051736_3DGaussTokens_ex1_gentle-boulevard/checkpoints/10-0.ckpt
LOCAL_RANK: 0 - CUDA_VISIBLE_DEVICES: [0]
  | Name        | Type          | Params
----------------------------------------------
0 | encoder     | Ptv3Encoder   | 46.4 M
1 | pre_quant   | Linear        | 8.3 K
2 | vq          | ResidualVQ    | 0
3 | pos_encoder | Sequential    | 4.3 K
4 | post_quant  | Linear        | 66.0 K
5 | decoder     | ResNetDecoder | 17.8 M
----------------------------------------------
64.3 M    Trainable params
0         Non-trainable params
64.3 M    Total params
257.162   Total estimated model params size (MB)
Restored all states from the checkpoint at ../3DGS-GPT/runs/02051736_3DGaussTokens_ex1_gentle-boulevard/checkpoints/10-0.ckpt
Max Steps | First cycle: 146000




Epoch 11:   1%|‚ñè               | 1/73 [01:01<1:14:20, 61.96s/it, v_num=line, train/loss=0.0824, train/vq_loss=0.0216]
Error executing job with overrides: []
Traceback (most recent call last):
  File "e:\User\Workspace\Review\2DGS-GPT\3DGS-GPT\train_vocabulary.py", line 273, in main
    trainer.fit(model, ckpt_path=resume)
  File "E:\User\Environment\Anaconda\MeshGPT\lib\site-packages\pytorch_lightning\trainer\trainer.py", line 531, in fit
    call._call_and_handle_interrupt(
  File "E:\User\Environment\Anaconda\MeshGPT\lib\site-packages\pytorch_lightning\trainer\call.py", line 41, in _call_and_handle_interrupt
    return trainer.strategy.launcher.launch(trainer_fn, *args, trainer=trainer, **kwargs)
  File "E:\User\Environment\Anaconda\MeshGPT\lib\site-packages\pytorch_lightning\strategies\launchers\subprocess_script.py", line 91, in launch
    return function(*args, **kwargs)
  File "E:\User\Environment\Anaconda\MeshGPT\lib\site-packages\pytorch_lightning\trainer\trainer.py", line 570, in _fit_impl
    self._run(model, ckpt_path=ckpt_path)
  File "E:\User\Environment\Anaconda\MeshGPT\lib\site-packages\pytorch_lightning\trainer\trainer.py", line 975, in _run
    results = self._run_stage()
  File "E:\User\Environment\Anaconda\MeshGPT\lib\site-packages\pytorch_lightning\trainer\trainer.py", line 1018, in _run_stage
    self.fit_loop.run()
  File "E:\User\Environment\Anaconda\MeshGPT\lib\site-packages\pytorch_lightning\loops\fit_loop.py", line 201, in run
    self.advance()
  File "E:\User\Environment\Anaconda\MeshGPT\lib\site-packages\pytorch_lightning\loops\fit_loop.py", line 354, in advance
    self.epoch_loop.run(self._data_fetcher)
  File "E:\User\Environment\Anaconda\MeshGPT\lib\site-packages\pytorch_lightning\loops\training_epoch_loop.py", line 133, in run
    self.advance(data_fetcher)
  File "E:\User\Environment\Anaconda\MeshGPT\lib\site-packages\pytorch_lightning\loops\training_epoch_loop.py", line 189, in advance
    batch = next(data_fetcher)
  File "E:\User\Environment\Anaconda\MeshGPT\lib\site-packages\pytorch_lightning\loops\fetchers.py", line 136, in __next__
    self._fetch_next_batch(self.dataloader_iter)
  File "E:\User\Environment\Anaconda\MeshGPT\lib\site-packages\pytorch_lightning\loops\fetchers.py", line 150, in _fetch_next_batch
    batch = next(iterator)
  File "E:\User\Environment\Anaconda\MeshGPT\lib\site-packages\pytorch_lightning\utilities\combined_loader.py", line 284, in __next__
    out = next(self._iterator)
  File "E:\User\Environment\Anaconda\MeshGPT\lib\site-packages\pytorch_lightning\utilities\combined_loader.py", line 65, in __next__
    out[i] = next(self.iterators[i])
  File "E:\User\Environment\Anaconda\MeshGPT\lib\site-packages\torch\utils\data\dataloader.py", line 630, in __next__
    data = self._next_data()
  File "E:\User\Environment\Anaconda\MeshGPT\lib\site-packages\torch\utils\data\dataloader.py", line 1345, in _next_data
    return self._process_data(data)
  File "E:\User\Environment\Anaconda\MeshGPT\lib\site-packages\torch\utils\data\dataloader.py", line 1371, in _process_data
    data.reraise()
  File "E:\User\Environment\Anaconda\MeshGPT\lib\site-packages\torch\_utils.py", line 694, in reraise
    raise exception
NameError: Caught NameError in DataLoader worker process 0.
Original Traceback (most recent call last):
  File "E:\User\Environment\Anaconda\MeshGPT\lib\site-packages\torch\utils\data\_utils\worker.py", line 308, in _worker_loop
    data = fetcher.fetch(index)
  File "E:\User\Environment\Anaconda\MeshGPT\lib\site-packages\torch\utils\data\_utils\fetch.py", line 51, in fetch
    data = [self.dataset[idx] for idx in possibly_batched_index]
  File "E:\User\Environment\Anaconda\MeshGPT\lib\site-packages\torch\utils\data\_utils\fetch.py", line 51, in <listcomp>
    data = [self.dataset[idx] for idx in possibly_batched_index]
  File "e:\User\Workspace\Review\2DGS-GPT\3DGS-GPT\dataset\Gaussian.py", line 168, in __getitem__
    return self.prepare_data(idx)
  File "e:\User\Workspace\Review\2DGS-GPT\3DGS-GPT\dataset\Gaussian.py", line 164, in prepare_data
    data_dict = self.transform_data(data_dict)
  File "e:\User\Workspace\Review\2DGS-GPT\3DGS-GPT\dataset\Gaussian.py", line 69, in transform_data
    data_dict = self._apply_rotation(data_dict, rotation_matrix)
  File "e:\User\Workspace\Review\2DGS-GPT\3DGS-GPT\dataset\Gaussian.py", line 103, in _apply_rotation
    rotated_quats = rotate_quaternions(quats, rot_mat)
NameError: name 'rotate_quaternions' is not defined
Set the environment variable HYDRA_FULL_ERROR=1 for a complete stack trace.